#VRML_SIM R2021b utf8
WorldInfo {
  coordinateSystem "NUE"
}
Viewpoint {
  orientation -0.6127488523488593 0.7371217820791128 0.284939155487042 1.1038491831062767
  position 3.73783885764296 4.423586939176064 3.3661523124720083
}
Background {
  skyColor [
    0.4 0.7 1
  ]
  luminosity 0
}
DEF FloorSolid Solid {
  children [
    DEF Floor Shape {
      appearance Appearance {
        material Material {
          diffuseColor 0.796078 0.572549 0.992157
        }
      }
      geometry Box {
        size 3 0.1 3
      }
    }
  ]
  name "solid(1)"
  boundingObject DEF Floor Shape {
    appearance Appearance {
      material Material {
        diffuseColor 0.796078 0.572549 0.992157
      }
    }
    geometry Box {
      size 3 0.1 3
    }
  }
}
DirectionalLight {
  direction 0 -1 -0.04
  castShadows TRUE
}
DEF Wall1 Solid {
  translation 0 0.16 1.46
  children [
    DEF Wall1 Shape {
      appearance Appearance {
        material Material {
          diffuseColor 0.00392157 0.054902 0.388235
        }
      }
      geometry Box {
        size 3 0.4 0.1
      }
    }
  ]
  boundingObject USE Wall1
}
DEF Wall2 Solid {
  translation 0 0.16 -1.45
  children [
    DEF Wall2 Shape {
      appearance Appearance {
        material Material {
          diffuseColor 0.00392157 0.054902 0.388235
        }
      }
      geometry Box {
        size 3 0.4 0.1
      }
    }
  ]
  boundingObject USE Wall2
}
DEF Wall3 Solid {
  translation -1.45 0.16 7e-07
  rotation 0 1 0 -1.5707953071795862
  children [
    DEF Wall3 Shape {
      appearance Appearance {
        material Material {
          diffuseColor 0.00392157 0.054902 0.388235
        }
      }
      geometry Box {
        size 3 0.4 0.1
      }
    }
  ]
  boundingObject USE Wall3
}
DEF Wall4 Solid {
  translation 1.46 0.16 -2.26715e-06
  rotation 0 1 0 -1.5707953071795862
  children [
    DEF Wall4 Shape {
      appearance Appearance {
        material Material {
          diffuseColor 0.00392157 0.054902 0.388235
        }
      }
      geometry Box {
        size 3 0.4 0.1
      }
    }
  ]
  boundingObject USE Wall4
}
DEF Cylinder Solid {
  translation 0.491438 0.30123 0.241676
  rotation -0.26296004831008535 -0.9321755343651268 -0.24879868593673862 0.004967205537718505
  children [
    Shape {
      appearance Appearance {
        material Material {
        }
      }
      geometry Cylinder {
        height 0.5
        radius 0.08
        subdivision 24
      }
    }
  ]
  name "robot"
  boundingObject Cylinder {
    height 0.5
    radius 0.08
  }
  physics Physics {
    density 130
  }
}
DEF Cylinder1 Solid {
  translation -0.2194 0.299572 0.720853
  rotation 0.9999657552679927 0.007500247842597511 -0.0034977955360784713 0.002978465204937813
  children [
    Shape {
      appearance Appearance {
        material Material {
        }
      }
      geometry Cylinder {
        height 0.5
        radius 0.15
        subdivision 24
      }
    }
  ]
  boundingObject Cylinder {
    height 0.5
    radius 0.15
  }
  physics Physics {
    density 130
  }
}
DEF Box Solid {
  translation 0.0875402 0.199044 -0.771832
  rotation 3.148025767814681e-16 1 3.1794890878074065e-16 0.07440826073511313
  children [
    Shape {
      appearance Appearance {
        material Material {
        }
      }
      geometry Box {
        size 0.25 0.3 0.25
      }
    }
  ]
  boundingObject Box {
    size 0.25 0.3 0.25
  }
  physics Physics {
    density 130
  }
}
DEF Cone Solid {
  translation -0.886672 0.295548 -0.382936
  rotation -0.058111183818914995 -0.998309316263959 -0.0012646642838369036 0.02132758607542236
  children [
    Shape {
      appearance Appearance {
        material Material {
        }
      }
      geometry Cone {
        bottomRadius 0.15
        height 0.5
      }
    }
  ]
  boundingObject Group {
    children [
      Transform {
        translation 0 0.11 0
        children [
          Cylinder {
            height 0.28
            radius 0.08
          }
        ]
      }
      Transform {
        translation 0 -0.12 0
        children [
          Cylinder {
            height 0.25
            radius 0.15
          }
        ]
      }
    ]
  }
  physics Physics {
    density 80
  }
}
DEF Sphere Solid {
  translation 0.895863 0.184196 -0.46238
  rotation -0.49635472494383476 -0.03099685299290847 0.8675662407738479 -3.1059117775392213
  children [
    Shape {
      appearance PBRAppearance {
        metalness 0.5
      }
      geometry Sphere {
        radius 0.15
        subdivision 5
      }
    }
  ]
  boundingObject Sphere {
    radius 0.15
    subdivision 5
  }
  physics Physics {
    density 100
  }
}
Robot {
  translation -1.0282709908460625 0.0921540272377698 1.2601301237715472
  rotation -0.02131040150453245 0.9997641348844736 -0.00418824383431811 -1.4795776345026672
  children [
    GPS {
      children [
        Solid {
          scale 0.7 0.7 0.7
          children [
            DEF gps Shape {
              appearance PBRAppearance {
                baseColor 0.00392157 0.054902 0.388235
              }
              geometry Cylinder {
                height 0.1
                radius 0.05
              }
            }
          ]
          boundingObject USE gps
        }
      ]
    }
    Camera {
      translation 0.00399992 0 0.135
      rotation 0 1 0 3.14159
      scale 0.25 0.25 0.25
      children [
        DEF camera Shape {
          appearance PBRAppearance {
            emissiveColor 0.666667 1 1
          }
          geometry Sphere {
            radius 0.1
          }
        }
      ]
      name "cam"
      boundingObject USE camera
      physics Physics {
      }
      recognition Recognition {
        frameThickness 5
      }
    }
    DistanceSensor {
      translation -0.04 0 0.15
      rotation 0 1 0 -1.87
      scale 0.08 0.08 0.08
      children [
        DEF distnt Shape {
          appearance PBRAppearance {
            emissiveColor 1 1 1
          }
          geometry Box {
            size 0.1 0.1 0.1
          }
        }
      ]
      name "ds_right"
      boundingObject USE distnt
      physics Physics {
      }
    }
    DEF distnt DistanceSensor {
      translation 0.04 0 0.15
      rotation 0 1 0 -1.27
      scale 0.08 0.08 0.08
      children [
        DEF distnt Shape {
          appearance PBRAppearance {
            emissiveColor 1 1 1
          }
          geometry Box {
            size 0.1 0.1 0.1
          }
        }
      ]
      name "ds_left"
      boundingObject USE distnt
      physics Physics {
      }
    }
    HingeJoint {
      jointParameters HingeJointParameters {
        position 1091.4227717060844
        anchor 0.1 0.01 0.07
      }
      device [
        DEF wheel1 RotationalMotor {
          name "wheel1"
        }
      ]
      endPoint Solid {
        translation 0.0999951 0.019443245105232515 0.07738363634820282
        rotation 0.6275312136257709 -0.627146014478911 -0.4614027009550168 4.006836474674511
        children [
          DEF Wheel Shape {
            appearance PBRAppearance {
            }
            geometry Cylinder {
              height 0.05
              radius 0.05
            }
          }
        ]
        name "solid(2)"
        boundingObject USE Wheel
        physics Physics {
        }
        linearVelocity -0.05660508058891848 0.007084889068128142 0.0031881268237324276
        angularVelocity 0.05004085505097584 -0.017118906312446967 0.9019851724005217
      }
    }
    HingeJoint {
      jointParameters HingeJointParameters {
        position 1027.4234611107665
        anchor -0.1 0.01 0.07
      }
      device [
        DEF wheel2 RotationalMotor {
          name "wheel2"
        }
      ]
      endPoint Solid {
        translation -0.1 0.0074106930337937155 0.07818565771995498
        rotation 0.7068382799498023 -0.7062770331755571 -0.03940048738705947 3.2204163197465565
        children [
          DEF Wheel Shape {
            appearance PBRAppearance {
            }
            geometry Cylinder {
              height 0.05
              radius 0.05
            }
          }
        ]
        name "solid(3)"
        boundingObject USE Wheel
        physics Physics {
        }
        linearVelocity -0.04521024752130056 -8.426646336770812e-05 0.002421138503639409
        angularVelocity 0.05004160717090086 -0.017118267150101552 0.9019887043752598
      }
    }
    HingeJoint {
      jointParameters HingeJointParameters {
        position 1091.4231320875874
        anchor 0.1 0.01 -0.07
      }
      device [
        DEF wheel3 RotationalMotor {
          name "wheel3"
        }
      ]
      endPoint Solid {
        translation 0.1 0.006929201539778773 -0.06933451968067977
        rotation 0.6260964006198454 -0.6255996170351994 -0.46543357882332276 4.013430081325957
        children [
          DEF Wheel Shape {
            appearance PBRAppearance {
            }
            geometry Cylinder {
              height 0.05
              radius 0.05
            }
          }
        ]
        name "solid(1)"
        boundingObject USE Wheel
        physics Physics {
        }
        linearVelocity -0.044983314874572466 -0.0003434899108650214 0.002707435943222534
        angularVelocity 0.05004087480320507 -0.017118961676619932 0.9019806384962259
      }
    }
    HingeJoint {
      jointParameters HingeJointParameters {
        position 1027.4235752718178
        anchor -0.1 0.01 -0.07
      }
      device [
        DEF wheel4 RotationalMotor {
          name "wheel4"
        }
      ]
      endPoint Solid {
        translation -0.1 0.004661910589694755 -0.07653578297815854
        rotation -0.7067684263688432 0.7062032552991492 0.04189694133220255 3.0572519041296977
        children [
          DEF Wheel Shape {
            appearance PBRAppearance {
            }
            geometry Cylinder {
              height 0.05
              radius 0.05
            }
          }
        ]
        boundingObject USE Wheel
        physics DEF Wheel_c Physics {
        }
        linearVelocity -0.04240119241681344 -0.0003322728867595936 0.002573118827361842
        angularVelocity 0.05004063565115967 -0.017118851970555734 0.9019844214666901
      }
    }
    DEF Body Shape {
      appearance PBRAppearance {
        baseColor 0.333333 1 0
        metalness 0.5
      }
      geometry Box {
        size 0.18 0.05 0.3
      }
    }
  ]
  name "robot(1)"
  boundingObject USE Body
  physics Physics {
    density 150
  }
  controller "Mid_Controller"
  linearVelocity -0.048647936949912235 0.005622534257656585 0.0031951238818978254
  angularVelocity -0.04141527896092259 -0.0013274720702972137 -0.09369911085357176
}
