#VRML_SIM R2021b utf8
WorldInfo {
  coordinateSystem "NUE"
}
Viewpoint {
  orientation -0.6479690742624239 -0.7145402183085056 -0.26375813773063106 1.0582833755086085
  position -3.6532313802605256 4.441482660518121 4.127898271564426
}
Background {
  skyColor [
    0.4 0.7 1
  ]
  luminosity 0
}
DEF FloorSolid Solid {
  children [
    DEF Floor Shape {
      appearance Appearance {
        material Material {
          diffuseColor 0.796078 0.572549 0.992157
        }
      }
      geometry Box {
        size 3 0.1 3
      }
    }
  ]
  name "solid(1)"
  boundingObject DEF Floor Shape {
    appearance Appearance {
      material Material {
        diffuseColor 0.796078 0.572549 0.992157
      }
    }
    geometry Box {
      size 3 0.1 3
    }
  }
}
DirectionalLight {
  direction 0 -1 -0.04
  castShadows TRUE
}
DEF Wall1 Solid {
  translation 0 0.16 1.46
  children [
    DEF Wall1 Shape {
      appearance Appearance {
        material Material {
          diffuseColor 0.00392157 0.054902 0.388235
        }
      }
      geometry Box {
        size 3 0.4 0.1
      }
    }
  ]
  boundingObject USE Wall1
}
DEF Wall2 Solid {
  translation 0 0.16 -1.45
  children [
    DEF Wall2 Shape {
      appearance Appearance {
        material Material {
          diffuseColor 0.00392157 0.054902 0.388235
        }
      }
      geometry Box {
        size 3 0.4 0.1
      }
    }
  ]
  boundingObject USE Wall2
}
DEF Wall3 Solid {
  translation -1.45 0.16 7e-07
  rotation 0 1 0 -1.5707953071795862
  children [
    DEF Wall3 Shape {
      appearance Appearance {
        material Material {
          diffuseColor 0.00392157 0.054902 0.388235
        }
      }
      geometry Box {
        size 3 0.4 0.1
      }
    }
  ]
  boundingObject USE Wall3
}
DEF Wall4 Solid {
  translation 1.46 0.16 -2.26715e-06
  rotation 0 1 0 -1.5707953071795862
  children [
    DEF Wall4 Shape {
      appearance Appearance {
        material Material {
          diffuseColor 0.00392157 0.054902 0.388235
        }
      }
      geometry Box {
        size 3 0.4 0.1
      }
    }
  ]
  boundingObject USE Wall4
}
DEF Cylinder Solid {
  translation 0.8453597505176781 0.2998946848760477 0.23401658490890964
  rotation 0.0009123725722428937 -0.9999725519021407 -0.007352755851372029 0.24552542949763861
  children [
    Shape {
      appearance Appearance {
        material Material {
        }
      }
      geometry Cylinder {
        height 0.5
        radius 0.08
        subdivision 24
      }
    }
  ]
  name "robot"
  boundingObject Cylinder {
    height 0.5
    radius 0.08
  }
  physics Physics {
    density 130
  }
  linearVelocity 0.000477884139372164 0.00012237052397903617 0.00011830976899018596
  angularVelocity 0.00047345296444074023 1.104887126563649e-09 -0.0019123716125817843
}
DEF Cylinder1 Solid {
  translation -0.21952042368666297 0.2995978078871069 0.7192369957963506
  rotation -0.9993437235357363 0.016415119086773275 0.0322903405850273 0.003128960508614631
  children [
    Shape {
      appearance Appearance {
        material Material {
        }
      }
      geometry Cylinder {
        height 0.5
        radius 0.15
        subdivision 24
      }
    }
  ]
  boundingObject Cylinder {
    height 0.5
    radius 0.15
  }
  physics Physics {
    density 130
  }
  linearVelocity -8.964290686901643e-05 0.0003249123606156813 -0.000853728390355146
  angularVelocity -0.0034229949853340786 2.03260275745216e-08 0.0003591973472806972
}
DEF Box Solid {
  translation 0.08566962846449207 0.1989963816451617 -0.7748543225321626
  rotation -0.035563528879531875 0.9993022936621528 0.011408825320552495 0.07760034582462212
  children [
    Shape {
      appearance Appearance {
        material Material {
        }
      }
      geometry Box {
        size 0.25 0.3 0.25
      }
    }
  ]
  boundingObject Box {
    size 0.25 0.3 0.25
  }
  physics Physics {
    density 130
  }
  linearVelocity -0.0005921892194006519 0.00017150606949881228 -0.000660333699414563
  angularVelocity -0.004088727047191661 5.54880615627004e-06 0.0036416750064707376
}
DEF Cone Solid {
  translation -0.5682236084266401 0.29467249616405083 -0.3822526393969894
  rotation -0.0039688309455195355 -0.9999267446930843 -0.011434755284522575 0.021167509919607138
  children [
    Shape {
      appearance Appearance {
        material Material {
        }
      }
      geometry Cone {
        bottomRadius 0.15
        height 0.5
      }
    }
  ]
  boundingObject Group {
    children [
      Transform {
        translation 0 0.11 0
        children [
          Cylinder {
            height 0.28
            radius 0.08
          }
        ]
      }
      Transform {
        translation 0 -0.12 0
        children [
          Cylinder {
            height 0.25
            radius 0.15
          }
        ]
      }
    ]
  }
  physics Physics {
    density 80
  }
  linearVelocity 1.3672489340285241e-06 1.1924195408945254e-06 -4.5839751257364793e-07
  angularVelocity -2.5432324215635605e-06 6.603869570770371e-18 -7.585625406053857e-06
}
DEF Sphere Solid {
  translation 0.895863 0.19778136173713975 -0.46238
  rotation -0.49635472494383476 -0.030996852992908466 0.8675662407738479 -3.1059117775392204
  children [
    Shape {
      appearance PBRAppearance {
        metalness 0.5
      }
      geometry Sphere {
        radius 0.15
        subdivision 5
      }
    }
  ]
  boundingObject Sphere {
    radius 0.15
    subdivision 5
  }
  physics Physics {
    density 100
  }
  linearVelocity 0 -2.6263062183726725e-06 0
}
Robot {
  translation 0.31749261744881513 0.09221187946136651 -0.537250586828445
  rotation -0.027202697446872724 -0.9991630416980746 -0.030548802861416244 3.0743285096369557
  children [
    GPS {
      children [
        Solid {
          scale 0.7 0.7 0.7
          children [
            DEF gps Shape {
              appearance PBRAppearance {
                baseColor 0.00392157 0.054902 0.388235
              }
              geometry Cylinder {
                height 0.1
                radius 0.05
              }
            }
          ]
          boundingObject USE gps
        }
      ]
    }
    Camera {
      translation 0.00399992 0 0.135
      rotation 0 1 0 3.14159
      scale 0.25 0.25 0.25
      children [
        DEF camera Shape {
          appearance PBRAppearance {
            emissiveColor 0.666667 1 1
          }
          geometry Sphere {
            radius 0.1
          }
        }
      ]
      name "cam"
      boundingObject USE camera
      physics Physics {
      }
      recognition Recognition {
        frameColor 0.666667 1 0
        frameThickness 5
      }
    }
    DistanceSensor {
      translation -0.04 0 0.15
      rotation 0 1 0 -1.87
      scale 0.08 0.08 0.08
      children [
        DEF distnt Shape {
          appearance PBRAppearance {
            emissiveColor 1 1 1
          }
          geometry Box {
            size 0.1 0.1 0.1
          }
        }
      ]
      name "ds_right"
      boundingObject USE distnt
      physics Physics {
      }
    }
    DistanceSensor {
      translation 0.04 0 0.15
      rotation 0 1 0 -1.27
      scale 0.08 0.08 0.08
      children [
        DEF distnt Shape {
          appearance PBRAppearance {
            emissiveColor 1 1 1
          }
          geometry Box {
            size 0.1 0.1 0.1
          }
        }
      ]
      name "ds_left"
      boundingObject USE distnt
      physics Physics {
      }
    }
    HingeJoint {
      jointParameters HingeJointParameters {
        position 2009.4044392696521
        anchor 0.1 0.01 0.07
      }
      device [
        DEF wheel1 RotationalMotor {
          name "wheel1"
        }
      ]
      endPoint Solid {
        translation 0.09999553000290817 0.01362936225332309 0.08145783506019327
        rotation 0.5110499545209741 -0.5107700827559052 -0.6913333975338064 4.352049874366876
        children [
          DEF Wheel Shape {
            appearance PBRAppearance {
            }
            geometry Cylinder {
              height 0.05
              radius 0.05
            }
          }
        ]
        name "solid(2)"
        boundingObject USE Wheel
        physics Physics {
        }
        linearVelocity -0.006566294132231853 -0.01953663973731017 -0.0017707105815346104
        angularVelocity -1.0424624173767827 0.05409260290853023 0.09589904453829151
      }
    }
    HingeJoint {
      jointParameters HingeJointParameters {
        position 1690.1108014741299
        anchor -0.1 0.01 0.07
      }
      device [
        DEF wheel2 RotationalMotor {
          name "wheel2"
        }
      ]
      endPoint Solid {
        translation -0.10001091771877157 0.010790538348975863 0.06144184144960045
        rotation -0.05129223625586152 0.05124327202659966 0.9973681534778824 1.572677809280091
        children [
          DEF Wheel Shape {
            appearance PBRAppearance {
            }
            geometry Cylinder {
              height 0.05
              radius 0.05
            }
          }
        ]
        name "solid(3)"
        boundingObject USE Wheel
        physics Physics {
        }
        linearVelocity -0.004769574971135629 0.005644662806465677 0.004273783689782866
        angularVelocity -1.0424579387700588 0.054093722216599666 0.09589601527887684
      }
    }
    HingeJoint {
      jointParameters HingeJointParameters {
        position 2009.4057529779875
        anchor 0.1 0.01 -0.07
      }
      device [
        DEF wheel3 RotationalMotor {
          name "wheel3"
        }
      ]
      endPoint Solid {
        translation 0.1000108032162701 0.007091647640468333 -0.07119961956031887
        rotation 0.5081567323953164 -0.5077508578210447 -0.6956765065052206 4.357926072667182
        children [
          DEF Wheel Shape {
            appearance PBRAppearance {
            }
            geometry Cylinder {
              height 0.05
              radius 0.05
            }
          }
        ]
        name "solid(1)"
        boundingObject USE Wheel
        physics Physics {
        }
        linearVelocity -0.00474154919608489 -0.0007811156869178464 0.007279211586533843
        angularVelocity -1.0424577975821767 0.05409243034306393 0.09589738870117497
      }
    }
    HingeJoint {
      jointParameters HingeJointParameters {
        position 1690.111303434844
        anchor -0.1 0.01 -0.07
      }
      device [
        DEF wheel4 RotationalMotor {
          name "wheel4"
        }
      ]
      endPoint Solid {
        translation -0.10000081667109689 0.016620255784029793 -0.06473833542937332
        rotation -0.04721432544472013 0.04753928047593023 0.9977528873847626 1.5722471257723944
        children [
          DEF Wheel Shape {
            appearance PBRAppearance {
            }
            geometry Cylinder {
              height 0.05
              radius 0.05
            }
          }
        ]
        boundingObject USE Wheel
        physics DEF Wheel_c Physics {
        }
        linearVelocity -0.005695839637918876 -0.0011820102664201221 -0.0032675688583834427
        angularVelocity -1.0424630394701517 0.05409175276431336 0.09589972863737861
      }
    }
    DEF Body Shape {
      appearance PBRAppearance {
        baseColor 0.333333 1 0
        metalness 0.5
      }
      geometry Box {
        size 0.18 0.05 0.3
      }
    }
  ]
  name "robot(1)"
  boundingObject USE Body
  physics Physics {
    density 150
  }
  controller "Mid_Controller"
  linearVelocity -0.004920285635634904 -0.0034226690005022247 0.004450016211750774
  angularVelocity -0.046193402090701746 0.001413222822933484 0.02755073518178377
}
